[Go系列教程](https://golangbot.com/learn-golang-series/) [Part32 Panic and Recover](https://golangbot.com/custom-errors/)

# 什么是 panic?

在 Go 程序中处理异常情况的惯用方法是使用 [errors](https://golangbot.com/error-handling/)。对于程序中产生的大多数异常情况，Errors就足够了。

但是有些情况，程序不能简单地在异常情况之后继续执行。在这种情况下我们使用 `panic` 来终止程序。当 [函数](https://golangbot.com/functions/) 产生 panic，它的执行被停止，任何 [deferred](https://golangbot.com/defer/) 函数都被执行，并且之后流程会返回给它的调用者。这个流程继续直到当前 [goroutine]() 的所有函数都停止，此时程序将显示 panic 消息，后面是堆栈跟踪，然后终止。我们写个示例程序，这个概念会更清晰。

使用 `recover` 重新获得 panic 程序的控制是可以的，`recover` 将稍后讨论。

*panic* 和 *recover* 可以认为和其他语言的惯用的 *try-catch-finally* 类似。不同之处在于它很少使用，并且使用时更优雅，并且代码干净。

# 何时应该使用 panic?

**一个重要的因素是你应该避免使用 panic 和 recove，并尽可能的使用 [errors](https://golangbot.com/error-handling/)。只有当程序不可以继续执行，应该使用一个 panic 和 recove 机制的情况下使用。**

下面是两个使用 panic 的合适用例。

1. *程序不能简单地继续执行的不可恢复的 error。*

   一个例子是 web 服务器，它不能够绑定到需要绑定的端口。在这种情况下，应该抛出 panic，因为端口绑定失败，无需要执行其他任何操作。

2. *程序员的错误*

   假设我们有个接收指针作为参数的方法，其他人使用 `nil` 作为参数调用该方法。这种情况下我们可以 panic，因为它是程序员使用 `nil` 参数调用方法的错误，而这期望的是一个有效的指针。

# Panic 示例

内置 `panic` 函数的签名如下：

```go
func panic(interface{})
```

当程序终止时，传递给 panic 的参数将会被打印。下面是一个例子以更好地理解它。

我们以一个展示 panic 如何工作的例子开始

```go
package main

import (  
    "fmt"
)

func fullName(firstName *string, lastName *string) {  
    if firstName == nil {
        panic("runtime error: first name cannot be nil")
    }
    if lastName == nil {
        panic("runtime error: last name cannot be nil")
    }
    fmt.Printf("%s %s\n", *firstName, *lastName)
    fmt.Println("returned normally from fullName")
}

func main() {  
    firstName := "Elon"
    fullName(&firstName, nil)
    fmt.Println("returned normally from main")
}
```

[Run in playground](https://play.golang.org/p/xQJYRSCu8S)

上面是打印人全名的例子程序。第7行的 `fullName` 函数打印人的全名。该程序在第8行和第11行分别检查 firstName 和 lastName 是否为 `nil`。如果为空，函数调用 `panic` 和相应的错误消息。当程序终止时，错误消息会被打印。

输出如下：

```shell
panic: runtime error: last name cannot be nil

goroutine 1 [running]:  
main.fullName(0x1040c128, 0x0)  
    /tmp/sandbox135038844/main.go:12 +0x120
main.main()  
    /tmp/sandbox135038844/main.go:20 +0x80
```

我们来分析这个输出以理解 panic 是如何工作的以及程序 panic 后，堆栈是如何打印的。

在第 19 行我们将 `Elon` 指定给 `firstName`。在第20行，使用 `lastName` 为 `nil` 来调用 `fullName` 函数。因此第11行的条件满足程序将 panic。当产生 panic时，程序执行终止，打印传递给 panic 的参数以及堆栈追踪。因此 panic 后面的第14行和15行将不被执行。程序首先打印传递给 `panic` 函数的消息

```shell
panic: runtime error: last name cannot be nil
```

然后打印堆栈追踪。

程序在第12行的 `fullName` 函数 panic，因此

```shell
main.fullName(0x1040c128, 0x0)  
    /tmp/sandbox135038844/main.go:12 +0x120
```

将会被先打印。然后下面的堆栈的下一项将会被打印。在例子中的第20行是 `fullName` 调用的堆栈追踪的下一项，它导致 panic 的发生。

```shell
main.main()
	/tmp/sandbox135038844/main.go:20 +0x80
```

被打印。现在，我们已经达到导致 panic 的顶层功能，并且上面没有其他层次，因此没有更多可打印的内容了。

# 当 panic 时 Defer 

我们来回顾一下 panic。**当函数产生 panic，它的执行停止，所有函数的延迟被执行，然后控制返回给它的调用者。流程继续直到当前 goroutine 的所有函数返回到程序打印 panic 消息的地方，后面跟前辈堆栈追踪，然后中止。**

在上面例子中，我们没用延迟调用任何函数。如果存在延迟函数调用，它被执行，然后控制返回给它的调用方。

我们使用 defer 语句对上面程序做一点修改

```go
package main

import (  
    "fmt"
)

func fullName(firstName *string, lastName *string) {  
    defer fmt.Println("deferred call in fullName")
    if firstName == nil {
        panic("runtime error: first name cannot be nil")
    }
    if lastName == nil {
        panic("runtime error: last name cannot be nil")
    }
    fmt.Printf("%s %s\n", *firstName, *lastName)
    fmt.Println("returned normally from fullName")
}

func main() {  
    defer fmt.Println("deferred call in main")
    firstName := "Elon"
    fullName(&firstName, nil)
    fmt.Println("returned normally from main")
}
```

[Run in playground](https://play.golang.org/p/oUFnu-uTmC)

上面程序唯一修改的地方是额外添加了延迟函数调用。

程序输出

```go
deferred call in fullName  
deferred call in main  
panic: runtime error: last name cannot be nil

goroutine 1 [running]:  
main.fullName(0x1042bf90, 0x0)  
    /tmp/sandbox060731990/main.go:13 +0x280
main.main()  
    /tmp/sandbox060731990/main.go:22 +0xc0
```

当程序在第13行 panic，首先执行所有的延迟函数调用，然后控制返回到执行延迟调用的调用者，依此类推，直到到达顶级调用者为止。

在我们的例子中，位于 `fullName` 函数的第8行的 `defer`首先被执行，打印

```shell
defered call in fullName
```

然后控制返回到 `main` 函数，它的延迟调用被执行，因此打印

```shell
defered call in main
```

现在控制已经到达顶级函数，因此程序将打印 panic 消息以及紧随其后的堆栈跟踪，然后中止。

# Recover

内置函数 `recover` 被用来恢复 panic 协程的控制。

recover 函数的签名提供如下：

```go
func recover() interface{}
```

仅在内部延迟函数中调用时，恢复才有用。在延迟函数内部执行一个 recover 调用，将通过存储正常的执行来停止 panicking 序列，并检查传递给 panic 的错误值。如果 recover 在 defer 函数外部被调用，则它将不会停止恐慌序列。

我们来修改我们的程序，在 panic 后使用 recover 存储正常执行。

```go
package main

import (  
    "fmt"
)

func recoverName() {  
    if r := recover(); r!= nil {
        fmt.Println("recovered from ", r)
    }
}

func fullName(firstName *string, lastName *string) {  
    defer recoverName()
    if firstName == nil {
        panic("runtime error: first name cannot be nil")
    }
    if lastName == nil {
        panic("runtime error: last name cannot be nil")
    }
    fmt.Printf("%s %s\n", *firstName, *lastName)
    fmt.Println("returned normally from fullName")
}

func main() {  
    defer fmt.Println("deferred call in main")
    firstName := "Elon"
    fullName(&firstName, nil)
    fmt.Println("returned normally from main")
}
```

[Run in playground](https://play.golang.org/p/I9pp8N55c1)

第7行的 `recoverName()` 函数调用 `recover()` 函数，该 `recover()` 函数将返回传递给 `panic` 的值。这里我们仅打印 recover 返回的值。`recoverName()` 在第14行的 `fullName` 函数内部被延迟调用。

当 `fullName` 发生 panic，延迟函数 `recoverName()` 被调用，它使用 `recover()` 来停止恐慌序列(panicking sequence)。

该程序打印

```shell
recovered from  runtime error: last name cannot be nil  
returned normally from main  
deferred call in main 
```

当程序在19行恐慌，延迟函数 `recoverName` 被调用，它反过来调用 `recover()` 来恢复恐慌协程的控制。第8行的 `recover()` 被调用，返回panic 的参数。

```shell
recovered from  runtime error: last name cannot be nil
```

在执行 `recover()` 后，panic 停止，同时控制返回给调用者，在这个例子中 `main` 函数和程序将从第29行 `main` 恐怖之后继续正常执行。

# Panic，Recover 和 协程

恢复仅当在被同一个[goroutine](https://golangbot.com/goroutines/)的调用时才会起作用。不可能从发生在不同协程的 panic 中恢复。我们来使用例子理解它。

```shell
package main

import (  
    "fmt"
    "time"
)

func recovery() {  
    if r := recover(); r != nil {
        fmt.Println("recovered:", r)
    }
}

func a() {  
    defer recovery()
    fmt.Println("Inside A")
    go b()
    time.Sleep(1 * time.Second)
}

func b() {  
    fmt.Println("Inside B")
    panic("oh! B panicked")
}

func main() {  
    a()
    fmt.Println("normally returned from main")
}
```

[Run in playground](https://play.golang.org/p/pEVzTLz36Y)

上面程序中，函数 `b()` 在23行 panic，函数 `a()` 调用延迟函数 `recovery()` ，它被用来从 panic 中恢复。在第17行，函数 `b()` 以一个独立的协程被调用，下一行的 `Sleep` 仅为了确保程序在 b() 完成运行之前不会中止。

程序会输出什么呢？panic会被恢复吗？当然不会！这是因为当前的恢复函数和发生在 panic 的 `b()` 在不同的协程中，因此恢复是不可能的。

运行程序会打印

```go
Inside A  
Inside B  
panic: oh! B panicked

goroutine 5 [running]:  
main.b()  
    /tmp/sandbox388039916/main.go:23 +0x80
created by main.a  
    /tmp/sandbox388039916/main.go:17 +0xc0
```

从输出中可以看到恢复并没有发生。

如果程序的第17行从

```go
go b()
```

修改为

```go
b()
```

现在由于panic 与recover在同一协程，将恢复将会发生。

```go
Inside A  
Inside B  
recovered: oh! B panicked  
normally returned from main 
```

# 运行时 panics

运行时错误也会导致 panic，例如数组访问越界。这和调用一个参数为接口类型[runtime.Error](https://golang.org/src/runtime/error.go?s=267:503#L1) 的内置 `panic` 函数是一样。接口 `runtime.Error` 的定义如下

```go
type Error interface {  
    error
    // RuntimeError is a no-op function but
    // serves to distinguish types that are run time
    // errors from ordinary errors: a type is a
    // run time error if it has a RuntimeError method.
    RuntimeError()
}
```

*runtime.Error*满足内置接口类型[error](https://golangbot.com/error-handling/#errortyperepresentation)。我们写一个人为的创建运行时panic 的例子。

```go
package main

import (  
    "fmt"
)

func a() {  
    n := []int{5, 7, 4}
    fmt.Println(n[3])
    fmt.Println("normally returned from a")
}
func main() {  
    a()
    fmt.Println("normally returned from main")
}
```

[Run in playground](https://play.golang.org/p/CBsK2xXzGg)

上面程序中，我们尝试访问 `n[3]`，这在 [slice](https://golangbot.com/arrays-and-slices/#slices) 中是个无效的索引。程序将 panic，并打印如下

```shell
panic: runtime error: index out of range

goroutine 1 [running]:  
main.a()  
    /tmp/sandbox780439659/main.go:9 +0x40
main.main()  
    /tmp/sandbox780439659/main.go:13 +0x20
```

是否可以从运行时 panic 中恢复呢。当然，我们修改上面程序，恢复 panic

```shell
package main

import (  
    "fmt"
)

func r() {  
    if r := recover(); r != nil {
        fmt.Println("Recovered", r)
    }
}

func a() {  
    defer r()
    n := []int{5, 7, 4}
    fmt.Println(n[3])
    fmt.Println("normally returned from a")
}

func main() {  
    a()
    fmt.Println("normally returned from main")
}
```

[Run in playground](https://play.golang.org/p/qusvZe5rft)

上面的程序输出如下：

```shell
Recovered runtime error: index out of range  
normally returned from main  
```

在恢复后获得堆栈追踪

如果我们恢复 panic，我们放松了 panic 的堆栈追踪。甚至在上面程序的恢复之后，我们丢失了堆栈追踪。

有种方法可以打印堆栈追踪，使用 [Debug](https://golang.org/pkg/runtime/debug/) 包的 [PrintStack](https://golang.org/pkg/runtime/debug/#PrintStack) 函数。

```go
package main

import (  
    "fmt"
    "runtime/debug"
)

func r() {  
    if r := recover(); r != nil {
        fmt.Println("Recovered", r)
        debug.PrintStack()
    }
}

func a() {  
    defer r()
    n := []int{5, 7, 4}
    fmt.Println(n[3])
    fmt.Println("normally returned from a")
}

func main() {  
    a()
    fmt.Println("normally returned from main")
}
```

[Run in playground](https://play.golang.org/p/D-QlDmumHV)

在上面程序中，我们使用 `debug.PrintStack()` 打印堆栈

```shell
Recovered runtime error: index out of range  
goroutine 1 [running]:  
runtime/debug.Stack(0x1042beb8, 0x2, 0x2, 0x1c)  
    /usr/local/go/src/runtime/debug/stack.go:24 +0xc0
runtime/debug.PrintStack()  
    /usr/local/go/src/runtime/debug/stack.go:16 +0x20
main.r()  
    /tmp/sandbox949178097/main.go:11 +0xe0
panic(0xf0a80, 0x17cd50)  
    /usr/local/go/src/runtime/panic.go:491 +0x2c0
main.a()  
    /tmp/sandbox949178097/main.go:18 +0x80
main.main()  
    /tmp/sandbox949178097/main.go:23 +0x20
normally returned from main  
```

从上面输入中，我们理解了首先 panic 被恢复，然后打印 `Recovered runtime error: index out of range` 然后是堆栈被打印。最后在恢复 panic 之后，`normally returned from main` 被打印。

下面是该教程的概括：

* 什么是 panic?
* 何时该使用 panic?
* Panic 示例
* 当 panic 后延迟调用 
* 恢复（recover）
* panic，Recover 和 Goroutines
* 运行时 panic
* 在恢复后获得堆栈追踪

**下一教程 - [头等函数(first class function)]()**











